<?xml version="1.0"?>
<!--
  Copyright 2015 Fadri Furrer, ASL, ETH Zurich, Switzerland
  Copyright 2015 Michael Burri, ASL, ETH Zurich, Switzerland
  Copyright 2015 Mina Kamel, ASL, ETH Zurich, Switzerland
  Copyright 2015 Janosch Nikolic, ASL, ETH Zurich, Switzerland
  Copyright 2015 Markus Achtelik, ASL, ETH Zurich, Switzerland

  Licensed under the Apache License, Version 2.0 (the "License");
  you may not use this file except in compliance with the License.
  You may obtain a copy of the License at

  http://www.apache.org/licenses/LICENSE-2.0

  Unless required by applicable law or agreed to in writing, software
  distributed under the License is distributed on an "AS IS" BASIS,
  WITHOUT WARRANTIES OR CONDITIONS OF ANY KIND, either express or implied.
  See the License for the specific language governing permissions and
  limitations under the License.
-->
<sdf version='1.6'>
  <model name='uav_box'>
      <link name='link_0'>
        <pose frame=''>0.012818 0.035334 0.100002 0 -0 0</pose>
        <inertial>
          <mass>1.42271</mass>
          <inertia>
            <ixx>0.237118</ixx>
            <ixy>0</ixy>
            <ixz>0</ixz>
            <iyy>0.358533</iyy>
            <iyz>0</iyz>
            <izz>0.358533</izz>
          </inertia>
          <pose frame=''>0 0 0 0 -0 0</pose>
        </inertial>
        <gravity>1</gravity>
        <self_collide>0</self_collide>
        <kinematic>0</kinematic>
        <visual name='visual'>
          <pose frame=''>0 0 0 0 -0 0</pose>
          <geometry>
            <box>
              <size>3 3 0.2</size>
            </box>
          </geometry>
          <material>
            <lighting>1</lighting>
            <script>
              <uri>file://media/materials/scripts/gazebo.material</uri>
              <name>Gazebo/Grey</name>
            </script>
            <shader type='pixel'>
              <normal_map>__default__</normal_map>
            </shader>
            <ambient>0.3 0.3 0.3 1</ambient>
            <diffuse>0.7 0.7 0.7 1</diffuse>
            <specular>0.01 0.01 0.01 1</specular>
            <emissive>0 0 0 1</emissive>
          </material>
          <transparency>0</transparency>
          <cast_shadows>1</cast_shadows>
        </visual>
        <collision name='collision'>
          <laser_retro>0</laser_retro>
          <max_contacts>10</max_contacts>
          <pose frame=''>0 0 0 0 -0 0</pose>
          <geometry>
            <box>
              <size>3 3 0.2</size>
            </box>
          </geometry>
          <surface>
            <friction>
              <ode>
                <mu>1</mu>
                <mu2>1</mu2>
                <fdir1>0 0 0</fdir1>
                <slip1>0</slip1>
                <slip2>0</slip2>
              </ode>
              <torsional>
                <coefficient>1</coefficient>
                <patch_radius>0</patch_radius>
                <surface_radius>0</surface_radius>
                <use_patch_radius>1</use_patch_radius>
                <ode>
                  <slip>0</slip>
                </ode>
              </torsional>
            </friction>
            <bounce>
              <restitution_coefficient>0</restitution_coefficient>
              <threshold>1e+06</threshold>
            </bounce>
            <contact>
              <collide_without_contact>0</collide_without_contact>
              <collide_without_contact_bitmask>1</collide_without_contact_bitmask>
              <collide_bitmask>1</collide_bitmask>
              <ode>
                <soft_cfm>0</soft_cfm>
                <soft_erp>0.2</soft_erp>
                <kp>1e+13</kp>
                <kd>1</kd>
                <max_vel>0.01</max_vel>
                <min_depth>0</min_depth>
              </ode>
              <bullet>
                <split_impulse>1</split_impulse>
                <split_impulse_penetration_threshold>-0.01</split_impulse_penetration_threshold>
                <soft_cfm>0</soft_cfm>
                <soft_erp>0.2</soft_erp>
                <kp>1e+13</kp>
                <kd>1</kd>
              </bullet>
            </contact>
          </surface>
        </collision>
      </link>
      <link name='link_1'>
        <pose frame=''>1.45 -0 0.3 0 -0 0</pose>
        <inertial>
          <mass>1</mass>
          <inertia>
            <ixx>0.166667</ixx>
            <ixy>0</ixy>
            <ixz>0</ixz>
            <iyy>0.166667</iyy>
            <iyz>0</iyz>
            <izz>0.166667</izz>
          </inertia>
          <pose frame=''>0 0 0 0 -0 0</pose>
        </inertial>
        <gravity>1</gravity>
        <self_collide>0</self_collide>
        <kinematic>0</kinematic>
        <visual name='visual'>
          <pose frame=''>0 0 0 0 -0 0</pose>
          <geometry>
            <box>
              <size>0.1 0.1 0.2</size>
            </box>
          </geometry>
          <material>
            <lighting>1</lighting>
            <script>
              <uri>file://media/materials/scripts/gazebo.material</uri>
              <name>Gazebo/Grey</name>
            </script>
            <shader type='pixel'>
              <normal_map>__default__</normal_map>
            </shader>
            <ambient>0.3 0.3 0.3 1</ambient>
            <diffuse>0.7 0.7 0.7 1</diffuse>
            <specular>0.01 0.01 0.01 1</specular>
            <emissive>0 0 0 1</emissive>
          </material>
          <transparency>0</transparency>
          <cast_shadows>1</cast_shadows>
        </visual>
        <collision name='collision'>
          <laser_retro>0</laser_retro>
          <max_contacts>10</max_contacts>
          <pose frame=''>0 0 0 0 -0 0</pose>
          <geometry>
            <box>
              <size>0.1 0.1 0.2</size>
            </box>
          </geometry>
          <surface>
            <friction>
              <ode>
                <mu>1</mu>
                <mu2>1</mu2>
                <fdir1>0 0 0</fdir1>
                <slip1>0</slip1>
                <slip2>0</slip2>
              </ode>
              <torsional>
                <coefficient>1</coefficient>
                <patch_radius>0</patch_radius>
                <surface_radius>0</surface_radius>
                <use_patch_radius>1</use_patch_radius>
                <ode>
                  <slip>0</slip>
                </ode>
              </torsional>
            </friction>
            <bounce>
              <restitution_coefficient>0</restitution_coefficient>
              <threshold>1e+06</threshold>
            </bounce>
            <contact>
              <collide_without_contact>0</collide_without_contact>
              <collide_without_contact_bitmask>1</collide_without_contact_bitmask>
              <collide_bitmask>1</collide_bitmask>
              <ode>
                <soft_cfm>0</soft_cfm>
                <soft_erp>0.2</soft_erp>
                <kp>1e+13</kp>
                <kd>1</kd>
                <max_vel>0.01</max_vel>
                <min_depth>0</min_depth>
              </ode>
              <bullet>
                <split_impulse>1</split_impulse>
                <split_impulse_penetration_threshold>-0.01</split_impulse_penetration_threshold>
                <soft_cfm>0</soft_cfm>
                <soft_erp>0.2</soft_erp>
                <kp>1e+13</kp>
                <kd>1</kd>
              </bullet>
            </contact>
          </surface>
        </collision>
      </link>
      <link name='link_1_clone'>
        <pose frame=''>-0 -1.45 0.300001 0 3e-06 0</pose>
        <inertial>
          <mass>1</mass>
          <inertia>
            <ixx>0.166667</ixx>
            <ixy>0</ixy>
            <ixz>0</ixz>
            <iyy>0.166667</iyy>
            <iyz>0</iyz>
            <izz>0.166667</izz>
          </inertia>
          <pose frame=''>0 0 0 0 -0 0</pose>
        </inertial>
        <self_collide>0</self_collide>
        <kinematic>0</kinematic>
        <gravity>1</gravity>
        <visual name='visual'>
          <pose frame=''>0 0 0 0 -0 0</pose>
          <geometry>
            <box>
              <size>0.1 0.1 0.2</size>
            </box>
          </geometry>
          <material>
            <lighting>1</lighting>
            <script>
              <uri>file://media/materials/scripts/gazebo.material</uri>
              <name>Gazebo/Grey</name>
            </script>
            <shader type='pixel'>
              <normal_map>__default__</normal_map>
            </shader>
            <ambient>0.3 0.3 0.3 1</ambient>
            <diffuse>0.7 0.7 0.7 1</diffuse>
            <specular>0.01 0.01 0.01 1</specular>
            <emissive>0 0 0 1</emissive>
          </material>
          <transparency>0</transparency>
          <cast_shadows>1</cast_shadows>
        </visual>
        <collision name='collision'>
          <laser_retro>0</laser_retro>
          <max_contacts>10</max_contacts>
          <pose frame=''>0 0 0 0 -0 0</pose>
          <geometry>
            <box>
              <size>0.1 0.1 0.2</size>
            </box>
          </geometry>
          <surface>
            <friction>
              <ode>
                <mu>1</mu>
                <mu2>1</mu2>
                <fdir1>0 0 0</fdir1>
                <slip1>0</slip1>
                <slip2>0</slip2>
              </ode>
              <torsional>
                <coefficient>1</coefficient>
                <patch_radius>0</patch_radius>
                <surface_radius>0</surface_radius>
                <use_patch_radius>1</use_patch_radius>
                <ode>
                  <slip>0</slip>
                </ode>
              </torsional>
            </friction>
            <bounce>
              <restitution_coefficient>0</restitution_coefficient>
              <threshold>1e+06</threshold>
            </bounce>
            <contact>
              <collide_without_contact>0</collide_without_contact>
              <collide_without_contact_bitmask>1</collide_without_contact_bitmask>
              <collide_bitmask>1</collide_bitmask>
              <ode>
                <soft_cfm>0</soft_cfm>
                <soft_erp>0.2</soft_erp>
                <kp>1e+13</kp>
                <kd>1</kd>
                <max_vel>0.01</max_vel>
                <min_depth>0</min_depth>
              </ode>
              <bullet>
                <split_impulse>1</split_impulse>
                <split_impulse_penetration_threshold>-0.01</split_impulse_penetration_threshold>
                <soft_cfm>0</soft_cfm>
                <soft_erp>0.2</soft_erp>
                <kp>1e+13</kp>
                <kd>1</kd>
              </bullet>
            </contact>
          </surface>
        </collision>
      </link>
      <link name='link_1_clone_clone'>
        <pose frame=''>-1.45 -0 0.300007 0 6e-06 0</pose>
        <inertial>
          <mass>1</mass>
          <inertia>
            <ixx>0.166667</ixx>
            <ixy>0</ixy>
            <ixz>0</ixz>
            <iyy>0.166667</iyy>
            <iyz>0</iyz>
            <izz>0.166667</izz>
          </inertia>
          <pose frame=''>0 0 0 0 -0 0</pose>
        </inertial>
        <self_collide>0</self_collide>
        <kinematic>0</kinematic>
        <gravity>1</gravity>
        <visual name='visual'>
          <pose frame=''>0 0 0 0 -0 0</pose>
          <geometry>
            <box>
              <size>0.1 0.1 0.2</size>
            </box>
          </geometry>
          <material>
            <lighting>1</lighting>
            <script>
              <uri>file://media/materials/scripts/gazebo.material</uri>
              <name>Gazebo/Grey</name>
            </script>
            <shader type='pixel'>
              <normal_map>__default__</normal_map>
            </shader>
            <ambient>0.3 0.3 0.3 1</ambient>
            <diffuse>0.7 0.7 0.7 1</diffuse>
            <specular>0.01 0.01 0.01 1</specular>
            <emissive>0 0 0 1</emissive>
          </material>
          <transparency>0</transparency>
          <cast_shadows>1</cast_shadows>
        </visual>
        <collision name='collision'>
          <laser_retro>0</laser_retro>
          <max_contacts>10</max_contacts>
          <pose frame=''>0 0 0 0 -0 0</pose>
          <geometry>
            <box>
              <size>0.1 0.1 0.2</size>
            </box>
          </geometry>
          <surface>
            <friction>
              <ode>
                <mu>1</mu>
                <mu2>1</mu2>
                <fdir1>0 0 0</fdir1>
                <slip1>0</slip1>
                <slip2>0</slip2>
              </ode>
              <torsional>
                <coefficient>1</coefficient>
                <patch_radius>0</patch_radius>
                <surface_radius>0</surface_radius>
                <use_patch_radius>1</use_patch_radius>
                <ode>
                  <slip>0</slip>
                </ode>
              </torsional>
            </friction>
            <bounce>
              <restitution_coefficient>0</restitution_coefficient>
              <threshold>1e+06</threshold>
            </bounce>
            <contact>
              <collide_without_contact>0</collide_without_contact>
              <collide_without_contact_bitmask>1</collide_without_contact_bitmask>
              <collide_bitmask>1</collide_bitmask>
              <ode>
                <soft_cfm>0</soft_cfm>
                <soft_erp>0.2</soft_erp>
                <kp>1e+13</kp>
                <kd>1</kd>
                <max_vel>0.01</max_vel>
                <min_depth>0</min_depth>
              </ode>
              <bullet>
                <split_impulse>1</split_impulse>
                <split_impulse_penetration_threshold>-0.01</split_impulse_penetration_threshold>
                <soft_cfm>0</soft_cfm>
                <soft_erp>0.2</soft_erp>
                <kp>1e+13</kp>
                <kd>1</kd>
              </bullet>
            </contact>
          </surface>
        </collision>
      </link>
      <link name='link_1_clone_clone_clone'>
        <pose frame=''>0 1.45 0.300008 0 9e-06 0</pose>
        <inertial>
          <mass>1</mass>
          <inertia>
            <ixx>0.166667</ixx>
            <ixy>0</ixy>
            <ixz>0</ixz>
            <iyy>0.166667</iyy>
            <iyz>0</iyz>
            <izz>0.166667</izz>
          </inertia>
          <pose frame=''>0 0 0 0 -0 0</pose>
        </inertial>
        <self_collide>0</self_collide>
        <kinematic>0</kinematic>
        <gravity>1</gravity>
        <visual name='visual'>
          <pose frame=''>0 0 0 0 -0 0</pose>
          <geometry>
            <box>
              <size>0.1 0.1 0.2</size>
            </box>
          </geometry>
          <material>
            <lighting>1</lighting>
            <script>
              <uri>file://media/materials/scripts/gazebo.material</uri>
              <name>Gazebo/Grey</name>
            </script>
            <shader type='pixel'>
              <normal_map>__default__</normal_map>
            </shader>
            <ambient>0.3 0.3 0.3 1</ambient>
            <diffuse>0.7 0.7 0.7 1</diffuse>
            <specular>0.01 0.01 0.01 1</specular>
            <emissive>0 0 0 1</emissive>
          </material>
          <transparency>0</transparency>
          <cast_shadows>1</cast_shadows>
        </visual>
        <collision name='collision'>
          <laser_retro>0</laser_retro>
          <max_contacts>10</max_contacts>
          <pose frame=''>0 0 0 0 -0 0</pose>
          <geometry>
            <box>
              <size>0.1 0.1 0.2</size>
            </box>
          </geometry>
          <surface>
            <friction>
              <ode>
                <mu>1</mu>
                <mu2>1</mu2>
                <fdir1>0 0 0</fdir1>
                <slip1>0</slip1>
                <slip2>0</slip2>
              </ode>
              <torsional>
                <coefficient>1</coefficient>
                <patch_radius>0</patch_radius>
                <surface_radius>0</surface_radius>
                <use_patch_radius>1</use_patch_radius>
                <ode>
                  <slip>0</slip>
                </ode>
              </torsional>
            </friction>
            <bounce>
              <restitution_coefficient>0</restitution_coefficient>
              <threshold>1e+06</threshold>
            </bounce>
            <contact>
              <collide_without_contact>0</collide_without_contact>
              <collide_without_contact_bitmask>1</collide_without_contact_bitmask>
              <collide_bitmask>1</collide_bitmask>
              <ode>
                <soft_cfm>0</soft_cfm>
                <soft_erp>0.2</soft_erp>
                <kp>1e+13</kp>
                <kd>1</kd>
                <max_vel>0.01</max_vel>
                <min_depth>0</min_depth>
              </ode>
              <bullet>
                <split_impulse>1</split_impulse>
                <split_impulse_penetration_threshold>-0.01</split_impulse_penetration_threshold>
                <soft_cfm>0</soft_cfm>
                <soft_erp>0.2</soft_erp>
                <kp>1e+13</kp>
                <kd>1</kd>
              </bullet>
            </contact>
          </surface>
        </collision>
      </link>
      <model name='ground_plane'>
        <static>1</static>
        <link name='link'>
          <collision name='collision'>
            <geometry>
              <plane>
                <normal>0 0 1</normal>
                <size>100 100</size>
              </plane>
            </geometry>
            <surface>
              <contact>
                <collide_bitmask>65535</collide_bitmask>
                <ode/>
              </contact>
              <friction>
                <ode>
                  <mu>100</mu>
                  <mu2>50</mu2>
                </ode>
                <torsional>
                  <ode/>
                </torsional>
              </friction>
              <bounce/>
            </surface>
            <max_contacts>10</max_contacts>
          </collision>
          <visual name='visual'>
            <cast_shadows>0</cast_shadows>
            <geometry>
              <plane>
                <normal>0 0 1</normal>
                <size>100 100</size>
              </plane>
            </geometry>
            <material>
              <script>
                <uri>file://media/materials/scripts/gazebo.material</uri>
                <name>Gazebo/Grey</name>
              </script>
            </material>
          </visual>
          <self_collide>0</self_collide>
          <kinematic>0</kinematic>
        </link>
        <pose frame=''>-1.89138 1.38203 6e-06 0 -0 0</pose>
      </model>
      
      <model name='quadrotor'>
        <link name='link'>
          <pose frame=''>0 0 0.182466 0 -0 0</pose>
          <inertial>
            <mass>1.316</mass>
            <inertia>
              <ixx>0.0128</ixx>
              <ixy>0</ixy>
              <ixz>0</ixz>
              <iyy>0.0128</iyy>
              <iyz>0</iyz>
              <izz>0.0218</izz>
            </inertia>
          </inertial>
          <collision name='collision'>
            <geometry>
              <mesh>
                <uri>model://quadrotor/meshes/quadrotor_base.dae</uri>
              </mesh>
            </geometry>
            <max_contacts>10</max_contacts>
            <surface>
              <contact>
                <ode/>
              </contact>
              <bounce/>
              <friction>
                <torsional>
                  <ode/>
                </torsional>
                <ode/>
              </friction>
            </surface>
          </collision>
          <visual name='visual'>
            <geometry>
              <mesh>
                <uri>model://quadrotor/meshes/quadrotor_base.dae</uri>
              </mesh>
            </geometry>
          </visual>
          <self_collide>0</self_collide>
          <kinematic>0</kinematic>
        </link>
        <pose frame=''>1.44739 0.002783 0.272444 0 -0 0</pose>
      </model>

      <model name='quadrotor_clone'>
        <link name='link'>
          <pose frame=''>0 0 0.182466 0 -0 0</pose>
          <inertial>
            <mass>1.316</mass>
            <inertia>
              <ixx>0.0128</ixx>
              <ixy>0</ixy>
              <ixz>0</ixz>
              <iyy>0.0128</iyy>
              <iyz>0</iyz>
              <izz>0.0218</izz>
            </inertia>
          </inertial>
          <collision name='collision'>
            <geometry>
              <mesh>
                <uri>model://quadrotor/meshes/quadrotor_base.dae</uri>
              </mesh>
            </geometry>
            <max_contacts>10</max_contacts>
            <surface>
              <contact>
                <ode/>
              </contact>
              <bounce/>
              <friction>
                <torsional>
                  <ode/>
                </torsional>
                <ode/>
              </friction>
            </surface>
          </collision>
          <visual name='visual'>
            <geometry>
              <mesh>
                <uri>model://quadrotor/meshes/quadrotor_base.dae</uri>
              </mesh>
            </geometry>
          </visual>
          <self_collide>0</self_collide>
          <kinematic>0</kinematic>
        </link>
        <pose frame=''>0.005533 -1.4474 0.272445 0 3e-06 -0.014073</pose>
      </model>
      <model name='quadrotor_clone_clone'>
        <link name='link'>
          <pose frame=''>0 0 0.182466 0 -0 0</pose>
          <inertial>
            <mass>1.316</mass>
            <inertia>
              <ixx>0.0128</ixx>
              <ixy>0</ixy>
              <ixz>0</ixz>
              <iyy>0.0128</iyy>
              <iyz>0</iyz>
              <izz>0.0218</izz>
            </inertia>
          </inertial>
          <collision name='collision'>
            <geometry>
              <mesh>
                <uri>model://quadrotor/meshes/quadrotor_base.dae</uri>
              </mesh>
            </geometry>
            <max_contacts>10</max_contacts>
            <surface>
              <contact>
                <ode/>
              </contact>
              <bounce/>
              <friction>
                <torsional>
                  <ode/>
                </torsional>
                <ode/>
              </friction>
            </surface>
          </collision>
          <visual name='visual'>
            <geometry>
              <mesh>
                <uri>model://quadrotor/meshes/quadrotor_base.dae</uri>
              </mesh>
            </geometry>
          </visual>
          <self_collide>0</self_collide>
          <kinematic>0</kinematic>
        </link>
        <pose frame=''>-1.44903 0.0062 0.272451 1e-06 6e-06 -0.000238</pose>
      </model>
      <model name='quadrotor_clone_clone_clone'>
        <link name='link'>
          <pose frame=''>0 0 0.182466 0 -0 0</pose>
          <inertial>
            <mass>1.316</mass>
            <inertia>
              <ixx>0.0128</ixx>
              <ixy>0</ixy>
              <ixz>0</ixz>
              <iyy>0.0128</iyy>
              <iyz>0</iyz>
              <izz>0.0218</izz>
            </inertia>
          </inertial>
          <collision name='collision'>
            <geometry>
              <mesh>
                <uri>model://quadrotor/meshes/quadrotor_base.dae</uri>
              </mesh>
            </geometry>
            <max_contacts>10</max_contacts>
            <surface>
              <contact>
                <ode/>
              </contact>
              <bounce/>
              <friction>
                <torsional>
                  <ode/>
                </torsional>
                <ode/>
              </friction>
            </surface>
          </collision>
          <visual name='visual'>
            <geometry>
              <mesh>
                <uri>model://quadrotor/meshes/quadrotor_base.dae</uri>
              </mesh>
            </geometry>
          </visual>
          <self_collide>0</self_collide>
          <kinematic>0</kinematic>
        </link>
        <pose frame=''>-0.00628 1.46231 0.272452 1e-06 9e-06 -0.017437</pose>
      </model>
      <joint name='link_0_JOINT_0' type='fixed'>
        <parent>link_0</parent>
        <child>link_1</child>
        <pose frame=''>0 0 0 0 -0 0</pose>
        <physics>
          <ode>
            <limit>
              <cfm>0</cfm>
              <erp>0.2</erp>
            </limit>
            <suspension>
              <cfm>0</cfm>
              <erp>0.2</erp>
            </suspension>
          </ode>
        </physics>
      </joint>
      <joint name='link_0_JOINT_1' type='fixed'>
        <parent>link_0</parent>
        <child>link_1_clone</child>
        <pose frame=''>0 0 0 0 -0 0</pose>
        <physics>
          <ode>
            <limit>
              <cfm>0</cfm>
              <erp>0.2</erp>
            </limit>
            <suspension>
              <cfm>0</cfm>
              <erp>0.2</erp>
            </suspension>
          </ode>
        </physics>
      </joint>
      <joint name='link_0_JOINT_2' type='fixed'>
        <parent>link_0</parent>
        <child>link_1_clone_clone</child>
        <pose frame=''>0 0 0 0 -0 0</pose>
        <physics>
          <ode>
            <limit>
              <cfm>0</cfm>
              <erp>0.2</erp>
            </limit>
            <suspension>
              <cfm>0</cfm>
              <erp>0.2</erp>
            </suspension>
          </ode>
        </physics>
      </joint>
      <joint name='link_0_JOINT_3' type='fixed'>
        <parent>link_0</parent>
        <child>link_1_clone_clone_clone</child>
        <pose frame=''>0 0 0 0 -0 0</pose>
        <physics>
          <ode>
            <limit>
              <cfm>0</cfm>
              <erp>0.2</erp>
            </limit>
            <suspension>
              <cfm>0</cfm>
              <erp>0.2</erp>
            </suspension>
          </ode>
        </physics>
      </joint>
      <joint name='link_0_JOINT_7' type='ball'>
        <parent>quadrotor_clone_clone::link</parent>
        <child>link_1_clone_clone</child>
        <pose frame=''>0 0 0 0 -0 0</pose>
        <physics>
          <ode>
            <limit>
              <cfm>0</cfm>
              <erp>0.2</erp>
            </limit>
            <suspension>
              <cfm>0</cfm>
              <erp>0.2</erp>
            </suspension>
          </ode>
        </physics>
        <sensor name="f_t0" type="force_torque">
          <update_rate>100</update_rate>
        </sensor>
      </joint>
      <plugin name="ft_sensor_plugin" filename="libgazebo_ros_ft_sensor.so">
        <updateRate>100.0</updateRate>
        <topicName>ft_sensor0</topicName>
        <jointName>link_0_JOINT_7</jointName>
      </plugin>

      <joint name='link_1_JOINT_5' type='ball'>
        <parent>quadrotor::link</parent>
        <child>link_1</child>
        <pose frame=''>0 0 0 0 -0 0</pose>
        <sensor name="f_t1" type="force_torque">
          <update_rate>100</update_rate>
        </sensor>
        <physics>
          <ode>
            <limit>
              <cfm>0</cfm>
              <erp>0.2</erp>
            </limit>
            <suspension>
              <cfm>0</cfm>
              <erp>0.2</erp>
            </suspension>
          </ode>
        </physics>
      </joint>
      <plugin name="ft_sensor_plugin" filename="libgazebo_ros_ft_sensor.so">
        <updateRate>100.0</updateRate>
        <topicName>ft_sensor1</topicName>
        <jointName>link_1_JOINT_5</jointName>
      </plugin>

      <joint name='link_1_clone_JOINT_6' type='ball'>
        <parent>quadrotor_clone::link</parent>
        <child>link_1_clone</child>
        <pose frame=''>0 0 0 0 -0 0</pose>
        <sensor name="f_t2" type="force_torque">
          <update_rate>100</update_rate>
        </sensor>
        <physics>
          <ode>
            <limit>
              <cfm>0</cfm>
              <erp>0.2</erp>
            </limit>
            <suspension>
              <cfm>0</cfm>
              <erp>0.2</erp>
            </suspension>
          </ode>
        </physics>
      </joint>
      <plugin name="ft_sensor_plugin" filename="libgazebo_ros_ft_sensor.so">
        <updateRate>100.0</updateRate>
        <topicName>ft_sensor2</topicName>
        <jointName>link_1_clone_JOINT_6</jointName>
      </plugin>

      <joint name='link_JOINT_8' type='ball'>
        <parent>quadrotor_clone_clone::link</parent>
        <child>link_1_clone_clone</child>
        <pose frame=''>0 0 0 0 -0 0</pose>
        <sensor name="f_t4" type="force_torque">
          <update_rate>100</update_rate>
        </sensor>
        <physics>
          <ode>
            <limit>
              <cfm>0</cfm>
              <erp>0.2</erp>
            </limit>
            <suspension>
              <cfm>0</cfm>
              <erp>0.2</erp>
            </suspension>
          </ode>
        </physics>
      </joint>
      <plugin name="ft_sensor_plugin" filename="libgazebo_ros_ft_sensor.so">
        <updateRate>100.0</updateRate>
        <topicName>ft_sensor3</topicName>
        <jointName>link_JOINT_8</jointName>
      </plugin>

      <static>0</static>
      <allow_auto_disable>1</allow_auto_disable>
      <pose frame=''>0.559692 -0.670207 0.059379 0 -3e-06 0.110238</pose>
    </model>
</sdf>

